Workbook

Sheet 1.INPUT 
A8: 1.INPUT

Sheet P&L ASSUMPTION 
B1: P&L assumptions | H1: Scenarios:
H2: Case 1 | I2: Optimistic | J2: Higher than historical average
H3: Case 2 | I3: Base | J3: Historical average
B4: Selected case | C4: 1 | H4: Case 3 | I4: Worst | J4: Worse than historical average
B6: INR in Crores | C6: FY14 | D6: FY15 | E6: FY16 | F6: FY17 | G6: FY18 | H6: FY19 | I6: FY20 | J6: FY21 | K6: FY22 | L6: FY23 | M6: FY24
B7: REVENUE | C7: ='INCOME STATEMENT'!C6 -> 27005.26 | D7: ='INCOME STATEMENT'!D6 -> 29020.98 | E7: ='INCOME STATEMENT'!E6 -> 30715.33 | F7: ='INCOME STATEMENT'!F6 -> 30983.66 | G7: ='INCOME STATEMENT'!G6 -> 33100.94 | H7: ='INCOME STATEMENT'!H6 -> 33972.23 | I7: =H7*(I8+1) -> 36350.286 | J7: =I7*(J8+1) -> 38894.806 | K7: =J7*(K8+1) -> 41617.443 | L7: =K7*(L8+1) -> 44530.664 | M7: =L7*(M8+1) -> 47647.81
B8: REVENUE GROWTH % | D8: =D7/C7-1 -> 0.074641755 | E8: =E7/D7-1 -> 0.058383625 | F8: =F7/E7-1 -> 0.0087360286 | G8: =G7/F7-1 -> 0.068335374 | H8: =H7/G7-1 -> 0.026322213 | I8: =CHOOSE($C$4,I11,I12,I13) -> 0.07 | J8: =CHOOSE($C$4,J11,J12,J13) -> 0.07 | K8: =CHOOSE($C$4,K11,K12,K13) -> 0.07 | L8: =CHOOSE($C$4,L11,L12,L13) -> 0.07 | M8: =CHOOSE($C$4,M11,M12,M13) -> 0.07
B11: Case 1 | I11: 0.07 | J11: 0.07 | K11: 0.07 | L11: 0.07 | M11: 0.07
B12: Case 2 | I12: 0.05 | J12: 0.05 | K12: 0.05 | L12: 0.05 | M12: 0.05
B13: Case 3 | I13: 0.03 | J13: 0.03 | K13: 0.03 | L13: 0.03 | M13: 0.03
B15: Cost of materials consumed | C15: ='INCOME STATEMENT'!C8 -> -18229.89 | D15: ='INCOME STATEMENT'!D8 -> -19715.3 | E15: ='INCOME STATEMENT'!E8 -> -19308.1 | F15: ='INCOME STATEMENT'!F8 -> -19116.08 | G15: ='INCOME STATEMENT'!G8 -> -21885.82 | H15: ='INCOME STATEMENT'!H8 -> -23444.42 | I15: =-I16*I7 -> -22537.177 | J15: =-J16*J7 -> -24114.78 | K15: =-K16*K7 -> -25802.814 | L15: =-L16*L7 -> -27609.011 | M15: =-M16*M7 -> -29541.642
B16: %SALES | C16: =-C15/C7 -> 0.6750496 | D16: =-D15/D7 -> 0.67934646 | E16: =-E15/E7 -> 0.62861444 | F16: =-F15/F7 -> 0.61697295 | G16: =-G15/G7 -> 0.66118424 | H16: =-H15/H7 -> 0.69010542 | I16: =CHOOSE($C$4,I18,I19,I20) -> 0.62 | J16: =CHOOSE($C$4,J18,J19,J20) -> 0.62 | K16: =CHOOSE($C$4,K18,K19,K20) -> 0.62 | L16: =CHOOSE($C$4,L18,L19,L20) -> 0.62 | M16: =CHOOSE($C$4,M18,M19,M20) -> 0.62
B18: Case 1 | I18: 0.62 | J18: 0.62 | K18: 0.62 | L18: 0.62 | M18: 0.62
B19: Case 2 | I19: 0.66 | J19: 0.66 | K19: 0.66 | L19: 0.66 | M19: 0.66
B20: Case 3 | I20: 0.69 | J20: 0.69 | K20: 0.69 | L20: 0.69 | M20: 0.69
B23: ='INCOME STATEMENT'!B9 -> Excise duty on sale of goods | C23: ='INCOME STATEMENT'!C9 -> -1880.35 | D23: ='INCOME STATEMENT'!D9 -> -1717.65 | E23: ='INCOME STATEMENT'!E9 -> -2258.21 | F23: ='INCOME STATEMENT'!F9 -> -2373.23 | G23: ='INCOME STATEMENT'!G9 -> -642.57 | H23: ='INCOME STATEMENT'!H9 -> -1.41 | I23: =I24/I7 -> 1.6545191e-09 | J23: =J24/J7 -> 1.5462795e-09 | K23: =K24/K7 -> 1.4451211e-09 | L23: =L24/L7 -> 1.3505804e-09 | M23: =M24/M7 -> 1.2622247e-09
B24: %SALES | C24: =C23/C15 -> 0.10314654 | D24: =D23/D15 -> 0.087122692 | E24: =E23/E15 -> 0.11695661 | F24: =F23/F15 -> 0.12414836 | G24: =G23/G15 -> 0.029360106 | H24: =H23/H15 -> 6.0142243e-05 | I24: =CHOOSE($C$4,I26,I27,I28) -> 6.0142243e-05 | J24: =CHOOSE($C$4,J26,J27,J28) -> 6.0142243e-05 | K24: =CHOOSE($C$4,K26,K27,K28) -> 6.0142243e-05 | L24: =CHOOSE($C$4,L26,L27,L28) -> 6.0142243e-05 | M24: =CHOOSE($C$4,M26,M27,M28) -> 6.0142243e-05
B26: Case 1 | I26: =H24 -> 6.0142243e-05 | J26: =I24 -> 6.0142243e-05 | K26: =J24 -> 6.0142243e-05 | L26: =K24 -> 6.0142243e-05 | M26: =L24 -> 6.0142243e-05
B27: Case 2 | I27: =H25 -> 0 | J27: =I25 -> 0 | K27: =J25 -> 0 | L27: =K25 -> 0 | M27: =L25 -> 0
B28: Case 3 | I28: =H26 -> 0 | J28: =I26 -> 6.0142243e-05 | K28: =J26 -> 6.0142243e-05 | L28: =K26 -> 6.0142243e-05 | M28: =L26 -> 6.0142243e-05
B31: ='INCOME STATEMENT'!B10 -> Employee benefits expenses | C31: ='INCOME STATEMENT'!C10 -> -930.35 | D31: ='INCOME STATEMENT'!D10 -> -1178.72 | E31: ='INCOME STATEMENT'!E10 -> -1339.46 | F31: ='INCOME STATEMENT'!F10 -> -1432.49 | G31: ='INCOME STATEMENT'!G10 -> -1583.71 | H31: ='INCOME STATEMENT'!H10 -> -1778.03 | I31: =-I32*I7 -> -1090.5086 | J31: =-J32*J7 -> -1166.8442 | K31: =-K32*K7 -> -1248.5233 | L31: =-L32*L7 -> -1335.9199 | M31: =-M32*M7 -> -1429.4343
B32: SALES% | C32: =-C31/C7 -> 0.034450696 | D32: =-D31/D7 -> 0.040616134 | E32: =-E31/E7 -> 0.043608843 | F32: =-F31/F7 -> 0.046233724 | G32: =-G31/G7 -> 0.047844865 | H32: =-H31/H7 -> 0.052337748 | I32: =CHOOSE($C$4,I34,I35,I36) -> 0.03 | J32: =CHOOSE($C$4,J34,J35,J36) -> 0.03 | K32: =CHOOSE($C$4,K34,K35,K36) -> 0.03 | L32: =CHOOSE($C$4,L34,L35,L36) -> 0.03 | M32: =CHOOSE($C$4,M34,M35,M36) -> 0.03
B34: Case 1 | I34: 0.03 | J34: 0.03 | K34: 0.03 | L34: 0.03 | M34: 0.03
B35: Case 2 | I35: 0.04 | J35: 0.04 | K35: 0.04 | L35: 0.04 | M35: 0.04
B36: Case 3 | I36: 0.05 | J36: 0.05 | K36: 0.05 | L36: 0.05 | M36: 0.05
B38: ='INCOME STATEMENT'!B11 -> Other expenses | C38: ='INCOME STATEMENT'!C11 -> -2425.57 | D38: ='INCOME STATEMENT'!D11 -> -2912.58 | E38: ='INCOME STATEMENT'!E11 -> -3411.86 | F38: ='INCOME STATEMENT'!F11 -> -3485.89 | G38: ='INCOME STATEMENT'!G11 -> -3663.79 | H38: ='INCOME STATEMENT'!H11 -> -3729.94 | I38: =-I39*I7 -> -3271.5257 | J38: =-J39*J7 -> -3500.5326 | K38: =-K39*K7 -> -3745.5698 | L38: =-L39*L7 -> -4007.7597 | M38: =-M39*M7 -> -4288.3029
B39: SALES% | C39: =-C38/C7 -> 0.089818428 | D39: =-D38/D7 -> 0.10036119 | E39: =-E38/E7 -> 0.11108004 | F39: =-F38/F7 -> 0.11250737 | G39: =-G38/G7 -> 0.11068538 | H39: =-H38/H7 -> 0.10979379 | I39: =CHOOSE($C$4,I41,I42,I43) -> 0.09 | J39: =CHOOSE($C$4,J41,J42,J43) -> 0.09 | K39: =CHOOSE($C$4,K41,K42,K43) -> 0.09 | L39: =CHOOSE($C$4,L41,L42,L43) -> 0.09 | M39: =CHOOSE($C$4,M41,M42,M43) -> 0.09
B41: Case 1 | I41: 0.09 | J41: 0.09 | K41: 0.09 | L41: 0.09 | M41: 0.09
B42: Case 2 | I42: 0.11 | J42: 0.11 | K42: 0.11 | L42: 0.11 | M42: 0.11
B43: Case 3 | I43: 0.11 | J43: 0.11 | K43: 0.11 | L43: 0.11 | M43: 0.11
B45: ='INCOME STATEMENT'!B14 -> Depreciation and amortisation expenses | C45: ='INCOME STATEMENT'!C14 -> -1107.37 | D45: ='INCOME STATEMENT'!D14 -> -540.45 | E45: ='INCOME STATEMENT'!E14 -> -443.25 | F45: ='INCOME STATEMENT'!F14 -> -502.25 | G45: ='INCOME STATEMENT'!G14 -> -574.98 | H45: ='INCOME STATEMENT'!H14 -> -624.44 | I45: =-I46*I7 -> -363.50286 | J45: =-J46*J7 -> -388.94806 | K45: =-K46*K7 -> -416.17443 | L45: =-L46*L7 -> -445.30664 | M45: =-M46*M7 -> -476.4781
B46: SALES% | C46: =-C45/C7 -> 0.041005715 | D46: =-D45/D7 -> 0.018622734 | E46: =-E45/E7 -> 0.014430905 | F46: =-F45/F7 -> 0.016210157 | G46: =-G45/G7 -> 0.017370504 | H46: =-H45/H7 -> 0.018380895 | I46: =CHOOSE($C$4,I48,I49,I50) -> 0.01 | J46: =CHOOSE($C$4,J48,J49,J50) -> 0.01 | K46: =CHOOSE($C$4,K48,K49,K50) -> 0.01 | L46: =CHOOSE($C$4,L48,L49,L50) -> 0.01 | M46: =CHOOSE($C$4,M48,M49,M50) -> 0.01
B48: Case 1 | I48: 0.01 | J48: 0.01 | K48: 0.01 | L48: 0.01 | M48: 0.01
B49: Case 2 | I49: 0.02 | J49: 0.02 | K49: 0.02 | L49: 0.02 | M49: 0.02
B50: Case 3 | I50: 0.04 | J50: 0.04 | K50: 0.04 | L50: 0.04 | M50: 0.04
B52: TAX% | C52: 0.34 | D52: 0.346 | E52: 0.346 | F52: 0.346 | G52: 0.35 | H52: 0.35 | I52: =CHOOSE($C$4,I54,I55,I56) -> 0.3 | J52: =CHOOSE($C$4,J54,J55,J56) -> 0.3 | K52: =CHOOSE($C$4,K54,K55,K56) -> 0.3 | L52: =CHOOSE($C$4,L54,L55,L56) -> 0.3 | M52: =CHOOSE($C$4,M54,M55,M56) -> 0.3
B54: Case 1 | I54: 0.3 | J54: 0.3 | K54: 0.3 | L54: 0.3 | M54: 0.3
B55: Case 2 | I55: 0.35 | J55: 0.35 | K55: 0.35 | L55: 0.35 | M55: 0.35
B56: Case 3 | I56: 0.35 | J56: 0.35 | K56: 0.35 | L56: 0.35 | M56: 0.35

Sheet BALANCE SHEET ASSUMPTION
B1: BS assumptions
B4: INR in Crores | C4: FY14 Actual | D4: FY15 Actual | E4: FY16 Actual | F4: FY17 Actual | G4: FY18 Actual | H4: FY19 Actual | I4: FY20 Forecast | J4: FY21 Forecast | K4: FY22 Forecast | L4: FY23 Forecast | M4: FY24 Forecast
B5: ACCOUNTS RECEVIABLE | C5: ='BALANCE SHEET'!C24 -> 920.58 | D5: ='BALANCE SHEET'!D24 -> 1371.82 | E5: ='BALANCE SHEET'!E24 -> 1282.08 | F5: ='BALANCE SHEET'!F24 -> 1551.75 | G5: ='BALANCE SHEET'!G24 -> 1426.97 | H5: ='BALANCE SHEET'!H24 -> 2745.11 | I5: =I6*'P&L ASSUMPTION '!I7/365 -> 2937.2677 | J5: =J6*'P&L ASSUMPTION '!J7/365 -> 3142.8764 | K5: =K6*'P&L ASSUMPTION '!K7/365 -> 3362.8778 | L5: =L6*'P&L ASSUMPTION '!L7/365 -> 3598.2792 | M5: =M6*'P&L ASSUMPTION '!M7/365 -> 3850.1588
B6: DSO | C6: =C5/'P&L ASSUMPTION '!C7*365 -> 12.442454 | D6: =D5/'P&L ASSUMPTION '!D7*365 -> 17.253528 | E6: =E5/'P&L ASSUMPTION '!E7*365 -> 15.235363 | F6: =F5/'P&L ASSUMPTION '!F7*365 -> 18.28024 | G6: =G5/'P&L ASSUMPTION '!G7*365 -> 15.735023 | H6: =H5/'P&L ASSUMPTION '!H7*365 -> 29.493653 | I6: =H6 -> 29.493653 | J6: =I6 -> 29.493653 | K6: =J6 -> 29.493653 | L6: =K6 -> 29.493653 | M6: =L6 -> 29.493653
B8: ACCONTS PAYABLE | C8: ='BALANCE SHEET'!C49 -> 2291.01 | D8: ='BALANCE SHEET'!D49 -> 2713.09 | E8: ='BALANCE SHEET'!E49 -> 2791.7 | F8: ='BALANCE SHEET'!F49 -> 3266.2 | G8: ='BALANCE SHEET'!G49 -> 3375.26 | H8: ='BALANCE SHEET'!H49 -> 3438.24 | I8: =-'BALANCE SHEET ASSUMPTION'!I9*'P&L ASSUMPTION '!I15/365 -> 3305.1884 | J8: =-'BALANCE SHEET ASSUMPTION'!J9*'P&L ASSUMPTION '!J15/365 -> 3536.5516 | K8: =-'BALANCE SHEET ASSUMPTION'!K9*'P&L ASSUMPTION '!K15/365 -> 3784.1102 | L8: =-'BALANCE SHEET ASSUMPTION'!L9*'P&L ASSUMPTION '!L15/365 -> 4048.9979 | M8: =-'BALANCE SHEET ASSUMPTION'!M9*'P&L ASSUMPTION '!M15/365 -> 4332.4278
B9: DPO | C9: =-C8/'P&L ASSUMPTION '!C15*365 -> 45.870746 | D9: =-D8/'P&L ASSUMPTION '!D15*365 -> 50.228901 | E9: =-E8/'P&L ASSUMPTION '!E15*365 -> 52.77425 | F9: =-F8/'P&L ASSUMPTION '!F15*365 -> 62.364407 | G9: =-G8/'P&L ASSUMPTION '!G15*365 -> 56.290781 | H9: =-H8/'P&L ASSUMPTION '!H15*365 -> 53.529053 | I9: =H9 -> 53.529053 | J9: =I9 -> 53.529053 | K9: =J9 -> 53.529053 | L9: =K9 -> 53.529053 | M9: =L9 -> 53.529053
B11: INVENTORY | C11: ='BALANCE SHEET'!C22 -> 669.55 | D11: ='BALANCE SHEET'!D22 -> 861.39 | E11: ='BALANCE SHEET'!E22 -> 761.99 | F11: ='BALANCE SHEET'!F22 -> 708.58 | G11: ='BALANCE SHEET'!G22 -> 962.68 | H11: ='BALANCE SHEET'!H22 -> 1249.53 | I11: =-I12*'P&L ASSUMPTION '!I15/365 -> 1201.1762 | J11: =-J12*'P&L ASSUMPTION '!J15/365 -> 1285.2585 | K11: =-K12*'P&L ASSUMPTION '!K15/365 -> 1375.2266 | L11: =-L12*'P&L ASSUMPTION '!L15/365 -> 1471.4925 | M11: =-M12*'P&L ASSUMPTION '!M15/365 -> 1574.497
B12: DIO | C12: =-C11/'P&L ASSUMPTION '!C15*365 -> 13.405772 | D12: =-D11/'P&L ASSUMPTION '!D15*365 -> 15.947378 | E12: =-E11/'P&L ASSUMPTION '!E15*365 -> 14.404646 | F12: =-F11/'P&L ASSUMPTION '!F15*365 -> 13.529536 | G12: =-G11/'P&L ASSUMPTION '!G15*365 -> 16.055062 | H12: =-H11/'P&L ASSUMPTION '!H15*365 -> 19.453603 | I12: =H12 -> 19.453603 | J12: =I12 -> 19.453603 | K12: =J12 -> 19.453603 | L12: =K12 -> 19.453603 | M12: =L12 -> 19.453603
B14: CCC | C14: =C6+C12-C9 -> -20.02252 | D14: =D6+D12-D9 -> -17.027994 | E14: =E6+E12-E9 -> -23.134241 | F14: =F6+F12-F9 -> -30.554631 | G14: =G6+G12-G9 -> -24.500696 | H14: =H6+H12-H9 -> -4.5817969 | I14: =I6+I12-I9 -> -4.5817969 | J14: =J6+J12-J9 -> -4.5817969 | ... M14: =M6+M12-M9 -> -4.5817969
B16: ='BALANCE SHEET'!B8 -> Property, plant and equipment | C16: =SUM('BALANCE SHEET'!C8:C11) -> 3102.03 | D16: =SUM('BALANCE SHEET'!D8:D11) -> 3671.48 | E16: =SUM('BALANCE SHEET'!E8:E11) -> 4689.46 | F16: =SUM('BALANCE SHEET'!F8:F11) -> 5179.81 | G16: =SUM('BALANCE SHEET'!G8:G11) -> 5316.44 | H16: =SUM('BALANCE SHEET'!H8:H11) -> 5525.18 | I16: =I17*'P&L ASSUMPTION '!I7 -> 5452.5429 | J16: =J17*'P&L ASSUMPTION '!J7 -> 5834.2209 | K16: =K17*'P&L ASSUMPTION '!K7 -> 6242.6164 | L16: =L17*'P&L ASSUMPTION '!L7 -> 6679.5995 | M16: =M17*'P&L ASSUMPTION '!M7 -> 7147.1715
B17: SALES% | C17: =C16/'P&L ASSUMPTION '!C7 -> 0.11486762 | D17: =D16/'P&L ASSUMPTION '!D7 -> 0.12651123 | E17: =E16/'P&L ASSUMPTION '!E7 -> 0.1526749 | F17: =F16/'P&L ASSUMPTION '!F7 -> 0.16717876 | G17: =G16/'P&L ASSUMPTION '!G7 -> 0.16061296 | H17: =H16/'P&L ASSUMPTION '!H7 -> 0.16263813 | I17: 0.15 | J17: 0.15 | K17: 0.15 | L17: 0.15 | M17: 0.15

Sheet 2.OUTPUT
A8: 2.OUTPUT

Sheet P&L
B1: P&L
B3: INR in Crores | C3: FY14 Actual | D3: FY15 Actual | E3: FY16 Actual | F3: FY17 Actual | G3: FY18 Actual | H3: FY19 Actual | I3: FY20 Forecast | J3: FY21 Forecast | K3: FY22 Forecast | L3: FY23 Forecast | M3: FY24 Forecast | O3: Note
B4: Net Revenues | C4: ='P&L ASSUMPTION '!C7 -> 27005.26 | D4: ='P&L ASSUMPTION '!D7 -> 29020.98 | E4: ='P&L ASSUMPTION '!E7 -> 30715.33 | F4: ='P&L ASSUMPTION '!F7 -> 30983.66 | G4: ='P&L ASSUMPTION '!G7 -> 33100.94 | H4: ='P&L ASSUMPTION '!H7 -> 33972.23 | I4: ='P&L ASSUMPTION '!I7 -> 36350.286 | J4: ='P&L ASSUMPTION '!J7 -> 38894.806 | ... M4: ='P&L ASSUMPTION '!M7 -> 47647.81
B5: Cost of goods sold | C5: ='P&L ASSUMPTION '!C15 -> -18229.89 | D5: ='P&L ASSUMPTION '!D15 -> -19715.3 | E5: ='P&L ASSUMPTION '!E15 -> -19308.1 | F5: ='P&L ASSUMPTION '!F15 -> -19116.08 | G5: ='P&L ASSUMPTION '!G15 -> -21885.82 | H5: ='P&L ASSUMPTION '!H15 -> -23444.42 | I5: ='P&L ASSUMPTION '!I15 -> -22537.177 | J5: ='P&L ASSUMPTION '!J15 -> -24114.78 | ... M5: ='P&L ASSUMPTION '!M15 -> -29541.642
B6: Gross Margin | C6: =C4+C5 -> 8775.37 | D6: =D4+D5 -> 9305.68 | E6: =E4+E5 -> 11407.23 | F6: =F4+F5 -> 11867.58 | G6: =G4+G5 -> 11215.12 | H6: =H4+H5 -> 10527.81 | I6: =I4+I5 -> 13813.109 | J6: =J4+J5 -> 14780.026 | ... M6: =M4+M5 -> 18106.168
B7: Excise duty | C7: ='P&L ASSUMPTION '!C23 -> -1880.35 | D7: ='P&L ASSUMPTION '!D23 -> -1717.65 | E7: ='P&L ASSUMPTION '!E23 -> -2258.21 | F7: ='P&L ASSUMPTION '!F23 -> -2373.23 | G7: ='P&L ASSUMPTION '!G23 -> -642.57 | H7: ='P&L ASSUMPTION '!H23 -> -1.41 | I7: ='P&L ASSUMPTION '!I23 -> 1.6545191e-09 | J7: ='P&L ASSUMPTION '!J23 -> 1.5462795e-09 | ... M7: ='P&L ASSUMPTION '!M23 -> 1.2622247e-09
B8: Employee benefits expenses | C8: ='P&L ASSUMPTION '!C31 -> -930.35 | D8: ='P&L ASSUMPTION '!D31 -> -1178.72 | E8: ='P&L ASSUMPTION '!E31 -> -1339.46 | F8: ='P&L ASSUMPTION '!F31 -> -1432.49 | G8: ='P&L ASSUMPTION '!G31 -> -1583.71 | H8: ='P&L ASSUMPTION '!H31 -> -1778.03 | I8: ='P&L ASSUMPTION '!I31 -> -1090.5086 | J8: ='P&L ASSUMPTION '!J31 -> -1166.8442 | ... M8: ='P&L ASSUMPTION '!M31 -> -1429.4343
B9: Other expenses | C9: ='P&L ASSUMPTION '!C38 -> -2425.57 | D9: ='P&L ASSUMPTION '!D38 -> -2912.58 | E9: ='P&L ASSUMPTION '!E38 -> -3411.86 | F9: ='P&L ASSUMPTION '!F38 -> -3485.89 | G9: ='P&L ASSUMPTION '!G38 -> -3663.79 | H9: ='P&L ASSUMPTION '!H38 -> -3729.94 | I9: ='P&L ASSUMPTION '!I38 -> -3271.5257 | J9: ='P&L ASSUMPTION '!J38 -> -3500.5326 | ... M9: ='P&L ASSUMPTION '!M38 -> -4288.3029
B10: EBITDA | C10: =C6+SUM(C7:C9) -> 3539.1 | D10: =D6+SUM(D7:D9) -> 3496.73 | E10: =E6+SUM(E7:E9) -> 4397.7 | F10: =F6+SUM(F7:F9) -> 4575.97 | G10: =G6+SUM(G7:G9) -> 5325.05 | H10: =H6+SUM(H7:H9) -> 5018.43 | I10: =I6+SUM(I7:I9) -> 9451.0744 | J10: =J6+SUM(J7:J9) -> 10112.65 | ... M10: =M6+SUM(M7:M9) -> 12388.431
B11: D&A | C11: ='P&L ASSUMPTION '!C45 -> -1107.37 | D11: ='P&L ASSUMPTION '!D45 -> -540.45 | E11: ='P&L ASSUMPTION '!E45 -> -443.25 | F11: ='P&L ASSUMPTION '!F45 -> -502.25 | G11: ='P&L ASSUMPTION '!G45 -> -574.98 | H11: ='P&L ASSUMPTION '!H45 -> -624.44 | I11: ='P&L ASSUMPTION '!I45 -> -363.50286 | J11: ='P&L ASSUMPTION '!J45 -> -388.94806 | ... M11: ='P&L ASSUMPTION '!M45 -> -476.4781
B12: EBIT | C12: =C10+C11 -> 2431.73 | D12: =D10+D11 -> 2956.28 | E12: =E10+E11 -> 3954.45 | F12: =F10+F11 -> 4073.72 | G12: =G10+G11 -> 4750.07 | H12: =H10+H11 -> 4393.99 | I12: =I10+I11 -> 9087.5715 | J12: =J10+J11 -> 9723.7015 | ... M12: =M10+M11 -> 11911.952
B13: Taxes | C13: =-C12*C14 -> -826.7882 | D13: =-D12*D14 -> -1022.8729 | E13: =-E12*E14 -> -1368.2397 | F13: =-F12*F14 -> -1409.5071 | G13: =-G12*G14 -> -1662.5245 | H13: =-H12*H14 -> -1537.8965 | I13: =-I12*I14 -> -2726.2715 | J13: =-J12*J14 -> -2917.1105 | ... M13: =-M12*M14 -> -3573.5857
B14: Tax rate | C14: ='P&L ASSUMPTION '!C52 -> 0.34 | D14: ='P&L ASSUMPTION '!D52 -> 0.346 | E14: ='P&L ASSUMPTION '!E52 -> 0.346 | F14: ='P&L ASSUMPTION '!F52 -> 0.346 | G14: ='P&L ASSUMPTION '!G52 -> 0.35 | H14: ='P&L ASSUMPTION '!H52 -> 0.35 | I14: ='P&L ASSUMPTION '!I52 -> 0.3 | J14: ='P&L ASSUMPTION '!J52 -> 0.3 | ... M14: ='P&L ASSUMPTION '!M52 -> 0.3
B15: Net Operating Profit After Taxes (NOPAT) | C15: =C12+C13 -> 1604.9418 | D15: =D12+D13 -> 1933.4071 | E15: =E12+E13 -> 2586.2103 | F15: =F12+F13 -> 2664.2129 | G15: =G12+G13 -> 3087.5455 | H15: =H12+H13 -> 2856.0935 | I15: =I12+I13 -> 6361.3001 | J15: =J12+J13 -> 6806.5911 | ... M15: =M12+M13 -> 8338.3667

Sheet BALANCE SHEET
B1: Balance Sheet
B3: INR in Crores | C3: FY14 Actual | D3: FY15 Actual | E3: FY16 Actual | F3: FY17 Actual | G3: FY18 Actual | H3: FY19 Actual | I3: FY20 Forecast | J3: FY21 Forecast | K3: FY22 Forecast | L3: FY23 Forecast | M3: FY24 Forecast | O3: Note
B4: Beginning PP&E | D4: =C7 -> 3102.03 | E4: =D7 -> 3671.48 | F4: =E7 -> 4689.46 | G4: =F7 -> 5179.81 | H4: =G7 -> 5316.44 | I4: =H7 -> 5525.18 | J4: =I7 -> 5452.5429 | K4: =J7 -> 5834.2209 | ... M4: =L7 -> 6679.5995
B5: Depreciation | C5: ='P&L ASSUMPTION '!C45 -> -1107.37 | D5: ='P&L ASSUMPTION '!D45 -> -540.45 | E5: ='P&L ASSUMPTION '!E45 -> -443.25 | F5: ='P&L ASSUMPTION '!F45 -> -502.25 | G5: ='P&L ASSUMPTION '!G45 -> -574.98 | H5: ='P&L ASSUMPTION '!H45 -> -624.44 | I5: ='P&L ASSUMPTION '!I45 -> -363.50286 | J5: ='P&L ASSUMPTION '!J45 -> -388.94806 | ... M5: ='P&L ASSUMPTION '!M45 -> -476.4781
B6: Capex | D6: =D7-D5-D4 -> 1109.9 | E6: =E7-E5-E4 -> 1461.23 | F6: =F7-F5-F4 -> 992.6 | G6: =G7-G5-G4 -> 711.61 | H6: =H7-H5-H4 -> 833.18 | I6: =I7-I5-I4 -> 290.86578 | J6: =J7-J5-J4 -> 770.62607 | K6: =K7-K5-K4 -> 824.56989 | ... M6: =M7-M5-M4 -> 944.05007
B7: Ending Value (PPE) | C7: ='BALANCE SHEET ASSUMPTION'!C16 -> 3102.03 | D7: ='BALANCE SHEET ASSUMPTION'!D16 -> 3671.48 | E7: ='BALANCE SHEET ASSUMPTION'!E16 -> 4689.46 | F7: ='BALANCE SHEET ASSUMPTION'!F16 -> 5179.81 | G7: ='BALANCE SHEET ASSUMPTION'!G16 -> 5316.44 | H7: ='BALANCE SHEET ASSUMPTION'!H16 -> 5525.18 | I7: ='BALANCE SHEET ASSUMPTION'!I16 -> 5452.5429 | J7: ='BALANCE SHEET ASSUMPTION'!J16 -> 5834.2209 | ... M7: ='BALANCE SHEET ASSUMPTION'!M16 -> 7147.1715
B9: Accounts Receivable | C9: ='BALANCE SHEET ASSUMPTION'!C5 -> 920.58 | D9: ='BALANCE SHEET ASSUMPTION'!D5 -> 1371.82 | E9: ='BALANCE SHEET ASSUMPTION'!E5 -> 1282.08 | F9: ='BALANCE SHEET ASSUMPTION'!F5 -> 1551.75 | G9: ='BALANCE SHEET ASSUMPTION'!G5 -> 1426.97 | H9: ='BALANCE SHEET ASSUMPTION'!H5 -> 2745.11 | I9: ='BALANCE SHEET ASSUMPTION'!I5 -> 2937.2677 | J9: ='BALANCE SHEET ASSUMPTION'!J5 -> 3142.8764 | ... M9: ='BALANCE SHEET ASSUMPTION'!M5 -> 3850.1588
B10: Inventory | C10: ='BALANCE SHEET ASSUMPTION'!C11 -> 669.55 | D10: ='BALANCE SHEET ASSUMPTION'!D11 -> 861.39 | E10: ='BALANCE SHEET ASSUMPTION'!E11 -> 761.99 | F10: ='BALANCE SHEET ASSUMPTION'!F11 -> 708.58 | G10: ='BALANCE SHEET ASSUMPTION'!G11 -> 962.68 | H10: ='BALANCE SHEET ASSUMPTION'!H11 -> 1249.53 | I10: ='BALANCE SHEET ASSUMPTION'!I11 -> 1201.1762 | J10: ='BALANCE SHEET ASSUMPTION'!J11 -> 1285.2585 | ... M10: ='BALANCE SHEET ASSUMPTION'!M11 -> 1574.497
B11: Accounts Payable | C11: ='BALANCE SHEET ASSUMPTION'!C8 -> 2291.01 | D11: ='BALANCE SHEET ASSUMPTION'!D8 -> 2713.09 | E11: ='BALANCE SHEET ASSUMPTION'!E8 -> 2791.7 | F11: ='BALANCE SHEET ASSUMPTION'!F8 -> 3266.2 | G11: ='BALANCE SHEET ASSUMPTION'!G8 -> 3375.26 | H11: ='BALANCE SHEET ASSUMPTION'!H8 -> 3438.24 | I11: ='BALANCE SHEET ASSUMPTION'!I8 -> 3305.1884 | J11: ='BALANCE SHEET ASSUMPTION'!J8 -> 3536.5516 | ... M11: ='BALANCE SHEET ASSUMPTION'!M8 -> 4332.4278
B12: Working capital | C12: =C9+C10-C11 -> -700.88 | D12: =D9+D10-D11 -> -479.88 | E12: =E9+E10-E11 -> -747.63 | F12: =F9+F10-F11 -> -1005.87 | G12: =G9+G10-G11 -> -985.61 | H12: =H9+H10-H11 -> 556.4 | I12: =I9+I10-I11 -> 833.25551 | J12: =J9+J10-J11 -> 891.58339 | ... M12: =M9+M10-M11 -> 1092.228
B13: Changes in working capital | D13: =D12-C12 -> 221 | E13: =E12-D12 -> -267.75 | F13: =F12-E12 -> -258.24 | G13: =G12-F12 -> 20.26 | H13: =H12-G12 -> 1542.01 | I13: =I12-H12 -> 276.85551 | J13: =J12-I12 -> 58.327886 | K13: =K12-J12 -> 62.410838 | ... M13: =M12-L12 -> 71.454168

Sheet DCF VALUTATION
B1: DCF Valuation
B3: WACC | C3: ='WACC '!C22 -> 0.088405353
B4: Terminal Growth | C4: 0.009
B6: INR in Crores | C6: FY15 Actual | D6: FY16 Actual | E6: FY17 Actual | F6: FY18 Actual | G6: FY19 Actual | H6: FY20 Forecast | I6: FY21 Forecast | J6: FY22 Forecast | K6: FY23 Forecast | L6: FY24 Forecast | N6: Note
B7: Net Cash Flow | C7: ='CASH FLOW '!C9 -> 1142.9571 | D7: ='CASH FLOW '!D9 -> 1835.9803 | E7: ='CASH FLOW '!E9 -> 2432.1029 | F7: ='CASH FLOW '!F9 -> 2930.6555 | G7: ='CASH FLOW '!G9 -> 1105.3435 | H7: ='CASH FLOW '!H9 -> 6157.0816 | I7: ='CASH FLOW '!I9 -> 6366.5852 | J7: ='CASH FLOW '!J9 -> 6812.2461 | ... L7: ='CASH FLOW '!L9 -> 7799.3406
B8: Discount factor | H8: =1/(1+$C$3)^1 -> 0.91877534 | I8: =1/(1+$C$3)^2 -> 0.84414813 | J8: =1/(1+$C$3)^3 -> 0.77558248 | K8: =1/(1+$C$3)^4 -> 0.71258606 | L8: =1/(1+$C$3)^5 -> 0.6547065
B9: Present Value | H9: =H7*H8 -> 5656.9748 | I9: =I7*I8 -> 5374.341 | J9: =J7*J8 -> 5283.4588 | K9: =K7*K8 -> 5194.1135 | L9: =L7*L8 -> 5106.279
B11: DCF VALUE | C11: =SUM(H9:L9) -> 26615.167 | D11: =C11/C14 -> 0.29087484
B12: CONTINUING VALUE | C12: =L7*(1+C4)/(C3-C4) -> 99105.846 | H12: SENSITIVITY ANALYSIS
B13: PRESENT VALUE OF CV | C13: =C12*L8 -> 64885.242 | D13: =C13/C14 -> 0.70912516
B14: ENTERPRISE VALUE | C14: =C11+C13 -> 91500.409 | H14: =C14 -> 91500.409 | I14: 0 | J14: 0.01 | K14: 0.02 | L14: 0.03 | M14: 0.04
B15: LESS | H15: 0.068 | I15: 110699.89 | J15: 125899.63 | K15: 147432.58 | L15: 180298.67 | M15: 236640.54
B16: DEBT | C16: ='BALANCE SHEET'!H48+'BALANCE SHEET'!H40 -> 308.52 | H16: 0.078 | I16: 96069.409 | J16: 106958.19 | K16: 121601.73 | L16: 142346.73 | M16: 174010.17
B17: ADD | H17: 0.088 | I17: 84778.523 | J17: 92887.481 | K17: 103381.43 | L17: 117493.97 | M17: 137486.75
B18: ='BALANCE SHEET'!B12 -> Equity accounted investments in associates | C18: ='BALANCE SHEET'!H12 -> 1705.89 | H18: 0.098 | I18: 75804.29 | J18: 82026.43 | K18: 89843.99 | L18: 99960.833 | M18: 113566.24
B19: ='BALANCE SHEET'!B13 -> Investments | C19: ='BALANCE SHEET'!H13 -> 1234.06 | H19: 0.108 | I19: 68502.662 | J19: 73391.989 | K19: 79392.525 | L19: 86931.661 | M19: 96688.19
B20: ='BALANCE SHEET'!B14 -> Loans to employees | C20: ='BALANCE SHEET'!H14 -> 60.12
B21: ='BALANCE SHEET'!B15 -> Security deposits | C21: ='BALANCE SHEET'!H15 -> 33.82
B22: ='BALANCE SHEET'!B16 -> Deferred tax assets (net) | C22: ='BALANCE SHEET'!H16 -> 0
B23: ='BALANCE SHEET'!B17 -> Income tax assets (net) | C23: ='BALANCE SHEET'!H17 -> 855.62
B24: ='BALANCE SHEET'!B18 -> Other non-current assets | C24: ='BALANCE SHEET'!H18 -> 676.46
B25: Investments | C25: ='BALANCE SHEET'!H23 -> 3173.88
B26: ='BALANCE SHEET'!B25 -> Cash and cash equivalents | C26: ='BALANCE SHEET'!H25 -> 208.12
B27: ='BALANCE SHEET'!B26 -> Bank balances | C27: ='BALANCE SHEET'!H26 -> 95.78
B28: ='BALANCE SHEET'!B27 -> Loans to employees | C28: ='BALANCE SHEET'!H27 -> 23.22
B29: ='BALANCE SHEET'!B28 -> Security deposits | C29: ='BALANCE SHEET'!H28 -> 1.86
B30: ='BALANCE SHEET'!B29 -> Others Financial Assets | C30: ='BALANCE SHEET'!H29 -> 654.19
B31: EQUITY VALUE | C31: =C14-C16+SUM(C18:C30) -> 99914.909
B32: SHARE OUTSTANDING | C32: 20
B33: intrinsic value | C33: =C31/C32 -> 4995.7454

Sheet PE RATIO
B1: Price to Earning ratio
B3: Company | C3: Price | D3: EPS | E3: PE
B4: Hero MotoCorp | C4: 2591 | D4: 172.42 | E4: =C4/D4 -> 15.027259
B5: Eicher Motors | C5: 15548 | D5: 807.45 | E5: =C5/D5 -> 19.255681
B6: TVS Motor | C6: 366.6 | D6: 14.83 | E6: =C6/D6 -> 24.720162
B7: Bajaj Auto | C7: 2737 | D7: 170.29 | E7: =C7/D7 -> 16.072582
B9: Hero MotoCorp | C9: Price | D9: EPS | E9: PE
B10: 41729 | C10: 2041.09 | D10: 94.23 | E10: =C10/D10 -> 21.660724
B11: 42094 | C11: 2021.47 | D11: 107.21 | E11: =C11/D11 -> 18.855237
B12: 42460 | C12: 2391.5 | D12: 143.09 | E12: =C12/D12 -> 16.713257
B13: 42825 | C13: 2818.3 | D13: 179.48 | E13: =C13/D13 -> 15.702585
B14: 43190 | C14: 3496.4 | D14: 186.3 | E14: =C14/D14 -> 18.767579
B15: 43555 | C15: 2553.15 | D15: 172.42 | E15: =C15/D15 -> 14.807737

Sheet CASH FLOW  
B1: Cash Flow
B2: .
B3: INR in Crores | C3: FY15 Actual | D3: FY16 Actual | E3: FY17 Actual | F3: FY18 Actual | G3: FY19 Actual | H3: FY20 Forecast | I3: FY21 Forecast | J3: FY22 Forecast | K3: FY23 Forecast | L3: FY24 Forecast | N3: Note
B4: Net Operating Profit After Taxes (NOPAT) | C4: ='P&L'!D15 -> 1933.4071 | D4: ='P&L'!E15 -> 2586.2103 | E4: ='P&L'!F15 -> 2664.2129 | F4: ='P&L'!G15 -> 3087.5455 | G4: ='P&L'!H15 -> 2856.0935 | H4: ='P&L'!I15 -> 6361.3001 | I4: ='P&L'!J15 -> 6806.5911 | J4: ='P&L'!K15 -> 7283.0524 | ... L4: ='P&L'!M15 -> 8338.3667
B5: Add: D&A | C5: =-'BALANCE SHEET'!D5 -> 540.45 | D5: =-'BALANCE SHEET'!E5 -> 443.25 | E5: =-'BALANCE SHEET'!F5 -> 502.25 | F5: =-'BALANCE SHEET'!G5 -> 574.98 | G5: =-'BALANCE SHEET'!H5 -> 624.44 | H5: =-'BALANCE SHEET'!I5 -> 363.50286 | I5: =-'BALANCE SHEET'!J5 -> 388.94806 | J5: =-'BALANCE SHEET'!K5 -> 416.17443 | ... L5: =-'BALANCE SHEET'!M5 -> 476.4781
B6: Gross Cash Flow | C6: =SUM(C4:C5) -> 2473.8571 | D6: =SUM(D4:D5) -> 3029.4603 | E6: =SUM(E4:E5) -> 3166.4629 | F6: =SUM(F4:F5) -> 3662.5255 | G6: =SUM(G4:G5) -> 3480.5335 | H6: =SUM(H4:H5) -> 6724.8029 | I6: =SUM(I4:I5) -> 7195.5391 | J6: =SUM(J4:J5) -> 7699.2269 | ... L6: =SUM(L4:L5) -> 8814.8448
B7: Less: Capex | C7: =-'BALANCE SHEET'!D6 -> -1109.9 | D7: =-'BALANCE SHEET'!E6 -> -1461.23 | E7: =-'BALANCE SHEET'!F6 -> -992.6 | F7: =-'BALANCE SHEET'!G6 -> -711.61 | G7: =-'BALANCE SHEET'!H6 -> -833.18 | H7: =-'BALANCE SHEET'!I6 -> -290.86578 | I7: =-'BALANCE SHEET'!J6 -> -770.62607 | J7: =-'BALANCE SHEET'!K6 -> -824.56989 | ... L7: =-'BALANCE SHEET'!M6 -> -944.05007
B8: Less: Investment in Working Capital | C8: =-'BALANCE SHEET'!D13 -> -221 | D8: =-'BALANCE SHEET'!E13 -> 267.75 | E8: =-'BALANCE SHEET'!F13 -> 258.24 | F8: =-'BALANCE SHEET'!G13 -> -20.26 | G8: =-'BALANCE SHEET'!H13 -> -1542.01 | H8: =-'BALANCE SHEET'!I13 -> -276.85551 | I8: =-'BALANCE SHEET'!J13 -> -58.327886 | J8: =-'BALANCE SHEET'!K13 -> -62.410838 | ... L8: =-'BALANCE SHEET'!M13 -> -71.454168
B9: Net Cash Flow | C9: =SUM(C6:C8) -> 1142.9571 | D9: =SUM(D6:D8) -> 1835.9803 | E9: =SUM(E6:E8) -> 2432.1029 | F9: =SUM(F6:F8) -> 2930.6555 | G9: =SUM(G6:G8) -> 1105.3435 | H9: =SUM(H6:H8) -> 6157.0816 | I9: =SUM(I6:I8) -> 6366.5852 | J9: =SUM(J6:J8) -> 6812.2461 | ... L9: =SUM(L6:L8) -> 7799.3406

Sheet WACC 
B2: Cost of Capital
E3: Date | F3: Hero MotoCorp Share price | G3: NSE500 | I3: Hero MotoCorp monthly return | J3: NSE500
B4: Key Inputs: | E4: 41883 | F4: 2468.34 | G4: 6415.7002
B5: Total Equity to Capital | C5: =C27/SUM(C27,C29) -> 0.99407044 | E5: 41913 | F5: 2659.02 | G5: 6685.75 | I5: =F5/F4-1 -> 0.077250298 | J5: =G5/G4-1 -> 0.042092024
B6: Net Debt to Capital | C6: =1-C5 -> 0.0059295625 | E6: 41944 | F6: 2729.02 | G6: 6918.0498 | I6: =F6/F5-1 -> 0.026325488 | J6: =G6/G5-1 -> 0.034745512
E7: 41974 | F7: 2695.32 | G7: 6773.6499 | I7: =F7/F6-1 -> -0.012348755 | J7: =G7/G6-1 -> -0.02087292
B8: Calculations: | E8: 42005 | F8: 2492.22 | G8: 7257.25 | I8: =F8/F7-1 -> -0.075352834 | J8: =G8/G7-1 -> 0.071394315
B9: Risk Free Rate | C9: 0.065 | E9: 42036 | F9: 2319.21 | G9: 7210.2998 | I9: =F9/F8-1 -> -0.069420035 | J9: =G9/G8-1 -> -0.0064694195
B10: Equity Beta | C10: =SLOPE(I5:I63,J5:J63) -> 0.47197298 | E10: 42064 | F10: 2295.11 | G10: 6978.1499 | I10: =F10/F9-1 -> -0.01039147 | J10: =G10/G9-1 -> -0.032196983
B11: Market Risk Premium | C11: 0.05 | E11: 42095 | F11: 2023.14 | G11: 6781.7002 | I11: =F11/F10-1 -> -0.11849977 | J11: =G11/G10-1 -> -0.028152119
B12: Cost of Equity | C12: =C9+C10*C11 -> 0.088598649 | E12: 42125 | F12: 2341.49 | G12: 6959.8501 | I12: =F12/F11-1 -> 0.15735441 | J12: =G12/G11-1 -> 0.026269209
E13: 42156 | F13: 2192.37 | G13: 6897.2002 | I13: =F13/F12-1 -> -0.063685944 | J13: =G13/G12-1 -> -0.0090016167
B14: Pre-tax cost of debt | C14: 0.08 | E14: 42186 | F14: 2348.91 | G14: 7106.2002 | I14: =F14/F13-1 -> 0.071402181 | J14: =G14/G13-1 -> 0.030302151
B15: Marginal Tax Rate | C15: ='P&L ASSUMPTION '!I52 -> 0.3 | E15: 42217 | F15: 2090.92 | G15: 6669.3501 | I15: =F15/F14-1 -> -0.10983392 | J15: =G15/G14-1 -> -0.061474499
B16: Cost of Debt | C16: =C14*(1-C15) -> 0.056 | E16: 42248 | F16: 2104.05 | G16: 6646.1001 | I16: =F16/F15-1 -> 0.0062795325 | J16: =G16/G15-1 -> -0.0034860968
E17: 42278 | F17: 2270.35 | G17: 6750.9502 | I17: =F17/F16-1 -> 0.079038046 | J17: =G17/G16-1 -> 0.015776184
E18: 42309 | F18: 2373.68 | G18: 6661.7002 | I18: =F18/F17-1 -> 0.045512806 | J18: =G18/G17-1 -> -0.013220361
B19: Weighted Cost of Equity | C19: =IF(ISNUMBER($C$5*$C$12),$C$5*$C$12,"N/A") -> 0.088073298 | E19: 42339 | F19: 2367.18 | G19: 6712.5 | I19: =F19/F18-1 -> -0.0027383641 | J19: =G19/G18-1 -> 0.0076256516
B20: Weighted Cost of Debt | C20: =IF(ISNUMBER($C$6*$C$16),$C$6*$C$16,"N/A") -> 0.0003320555 | E20: 42370 | F20: 2250.85 | G20: 6753.65 | I20: =F20/F19-1 -> -0.049142862 | J20: =G20/G19-1 -> 0.0061303538
E21: 42401 | F21: 2195.39 | G21: 6341.6 | I21: =F21/F20-1 -> -0.024639581 | J21: =G21/G20-1 -> -0.061011453
B22: Weighted Average Cost of Capital | C22: =SUM(C19:C20) -> 0.088405353 | E22: 42430 | F22: 2585.13 | G22: 6020.05 | I22: =F22/F21-1 -> 0.17752654 | J22: =G22/G21-1 -> -0.050704869
E23: 42461 | F23: 2584.65 | G23: 6445.5 | I23: =F23/F22-1 -> -0.00018567732 | J23: =G23/G22-1 -> 0.07067217
E24: 42491 | F24: 2760.9 | G24: 6580.15 | I24: =F24/F23-1 -> 0.068191051 | J24: =G24/G23-1 -> 0.020890544
B25: Shares outstanding | C25: 19.97 | E25: 42522 | F25: 2833.68 | G25: 6815.45 | I25: =F25/F24-1 -> 0.026360969 | J25: =G25/G24-1 -> 0.035759063
B26: Share price | C26: 2590 | E26: 42552 | F26: 2856.49 | G26: 7027.85 | I26: =F26/F25-1 -> 0.0080496033 | J26: =G26/G25-1 -> 0.031164487
B27: Market Cap | C27: =C25*C26 -> 51722.3 | E27: 42583 | F27: 3160.32 | G27: 7335.05 | I27: =F27/F26-1 -> 0.1063648 | J27: =G27/G26-1 -> 0.043711804
E28: 42614 | F28: 3041.7 | G28: 7474.3 | I28: =F28/F27-1 -> -0.037534174 | J28: =G28/G27-1 -> 0.018984192
B29: Debt | C29: ='BALANCE SHEET'!H48+'BALANCE SHEET'!H40 -> 308.52 | E29: 42644 | F29: 3010 | G29: 7532.25 | I29: =F29/F28-1 -> -0.010421804 | J29: =G29/G28-1 -> 0.0077532344
C30: =C27+C29 -> 52030.82 | E30: 42675 | F30: 2848.52 | G30: 7502.2 | I30: =F30/F29-1 -> -0.053647841 | J30: =G30/G29-1 -> -0.0039895118
E31: 42705 | F31: 2949.33 | G31: 7040.25 | I31: =F31/F30-1 -> 0.035390308 | J31: =G31/G30-1 -> -0.061575271
E32: 42736 | F32: 2857.74 | G32: 7379.2998 | I32: =F32/F31-1 -> -0.031054511 | J32: =G32/G31-1 -> 0.048158773
E33: 42767 | F33: 2817.96 | G33: 7709.1001 | I33: =F33/F32-1 -> -0.013920091 | J33: =G33/G32-1 -> 0.044692627
E34: 42795 | F34: 2897.83 | G34: 7995.0498 | I34: =F34/F33-1 -> 0.028343199 | J34: =G34/G33-1 -> 0.037092489
E35: 42826 | F35: 3042.47 | G35: 8214.2998 | I35: =F35/F34-1 -> 0.049913211 | J35: =G35/G34-1 -> 0.027423219
E36: 42856 | F36: 3419.62 | G36: 8350.9502 | I36: =F36/F35-1 -> 0.12396178 | J36: =G36/G35-1 -> 0.016635671
E37: 42887 | F37: 3377.5 | G37: 8331.5996 | I37: =F37/F36-1 -> -0.012317158 | J37: =G37/G36-1 -> -0.0023171718
E38: 42917 | F38: 3365.73 | G38: 8793.2998 | I38: =F38/F37-1 -> -0.0034848261 | J38: =G38/G37-1 -> 0.055415553
E39: 42948 | F39: 3682.58 | G39: 8694.9502 | I39: =F39/F38-1 -> 0.094140053 | J39: =G39/G38-1 -> -0.011184608
E40: 42979 | F40: 3482.8 | G40: 8600 | I40: =F40/F39-1 -> -0.05425001 | J40: =G40/G39-1 -> -0.010920154
E41: 43009 | F41: 3550.55 | G41: 9153.5996 | I41: =F41/F40-1 -> 0.019452739 | J41: =G41/G40-1 -> 0.064372048
...

Sheet 3.SOURCE
A8: 3.SOURCE

Sheet INCOME STATEMENT
A1: HEROMOTOCORP LTD
B2: Income Statement
B3: INR (cr)
B5: Particulars | C5: 41699 | D5: 42064 | E5: 42430 | F5: 42795 | G5: 43160 | H5: 43525
B6: Revenue from operations | C6: 27005.26 | D6: 29020.98 | E6: 30715.33 | F6: 30983.66 | G6: 33100.94 | H6: 33972.23 | I6: Operating item
B7: Operating expenses
B8: Cost of materials consumed | C8: -18229.89 | D8: -19715.3 | E8: -19308.1 | F8: -19116.08 | G8: -21885.82 | H8: -23444.42 | I8: Operating item
B9: Excise duty on sale of goods | C9: -1880.35 | D9: -1717.65 | E9: -2258.21 | F9: -2373.23 | G9: -642.57 | H9: -1.41 | I9: Operating item
B10: Employee benefits expenses | C10: -930.35 | D10: -1178.72 | E10: -1339.46 | F10: -1432.49 | G10: -1583.71 | H10: -1778.03 | I10: Operating item
B11: Other expenses | C11: -2425.57 | D11: -2912.58 | E11: -3411.86 | F11: -3485.89 | G11: -3663.79 | H11: -3729.94 | I11: Operating item
B12: Total operating expenses | C12: -23466.16 | D12: -25524.25 | E12: -26317.63 | F12: -26407.69 | G12: -27775.89 | H12: -28953.8
B13: EBITDA | C13: 3539.1 | D13: 3496.73 | E13: 4397.7 | F13: 4575.97 | G13: 5325.05 | H13: 5018.43
B14: Depreciation and amortisation expenses | C14: -1107.37 | D14: -540.45 | E14: -443.25 | F14: -502.25 | G14: -574.98 | H14: -624.44 | I14: Operating item
B15: EBIT | C15: 2431.73 | D15: 2956.28 | E15: 3954.45 | F15: 4073.72 | G15: 4750.07 | H15: 4393.99
B16: Other income | C16: 444.19 | D16: 347.38 | E16: 412.83 | F16: 521.95 | G16: 523.17 | H16: 686.73 | I16: Non Operating item
B17: Finance costs | C17: -11.82 | D17: -11.7 | E17: -14.61 | F17: -27.28 | G17: -30.8 | H17: -37.18 | I17: Non Operating item
B18: Share in profit/(loss) of associates, net of tax | C18: -3.62 | D18: 15.15 | E18: 34.33 | F18: 54.92 | G18: 49.66 | H18: 60.76 | I18: Non Operating item
B19: Gain on dilution of interest in an associate | E19: 0 | F19: 262.09 | G19: 0 | H19: 0 | I19: Non Operating item
B20: Minority interest profit/(loss) | C20: 0.35 | D20: 1.04 | E20: 4.11 | F20: 0 | G20: 0 | H20: 0
B21: Profit before tax | C21: 2860.83 | D21: 3308.15 | E21: 4391.11 | F21: 4885.4 | G21: 5292.1 | H21: 5104.3
B22: Tax expense | C22: -758.17 | D22: -943.45 | E22: -1274.71 | F22: -1339.1 | G22: -1569.93 | H22: -1637.95 | I22: Operating item
B23: Profit after tax / Net profit | C23: 2102.66 | D23: 2364.7 | E23: 3116.4 | F23: 3546.3 | G23: 3722.17 | H23: 3466.35

Sheet BALANCE  SHEET
A1: HEROMOTOCORP LTD
B2: Balance Sheet
B3: INR (cr)
B5: Particulars | C5: 41699 | D5: 42064 | E5: 42430 | F5: 42795 | G5: 43160 | H5: 43525
B6: ASSETS
B7: NON-CURRENT ASSETS
B8: Property, plant and equipment | C8: 1897.37 | D8: 2850.86 | E8: 3907.02 | F8: 4495.03 | G8: 4771.39 | H8: 4792.5 | I8: Operating item
B9: Capital work-in-progress | C9: 854.74 | D9: 315.12 | E9: 330.78 | F9: 386.5 | G9: 239.02 | H9: 384.85 | I9: Operating item
B10: Intangible assets | C10: 349.92 | D10: 101.42 | E10: 129.07 | F10: 103.82 | G10: 189.57 | H10: 159.86 | I10: Operating item
B11: Intangible assets under development | C11: 0 | D11: 404.08 | E11: 322.59 | F11: 194.46 | G11: 116.46 | H11: 187.97 | I11: Operating item
B12: Equity accounted investments in associates | C12: 0 | D12: 708.46 | E12: 950.07 | F12: 1025.37 | G12: 1159.63 | H12: 1705.89 | I12: Non Operating item
B13: Investments | C13: 877.86 | D13: 821.15 | E13: 945.26 | F13: 496.94 | G13: 918.49 | H13: 1234.06 | I13: Non Operating item
B14: Loans to employees | C14: 477.43 | D14: 0 | E14: 0 | F14: 23.13 | G14: 22.3 | H14: 60.12 | I14: Non Operating item
B15: Security deposits | C15: 0 | D15: 0 | E15: 0 | F15: 25.39 | G15: 23.55 | H15: 33.82 | I15: Operating item
B16: Deferred tax assets (net) | C16: 105.98 | D16: 73.54 | E16: 0 | F16: 0 | G16: 0 | H16: 0 | I16: Non Operating item
B17: Income tax assets (net) | C17: 0 | D17: 0 | E17: 0 | F17: 332.5 | G17: 394.51 | H17: 855.62 | I17: Operating item
B18: Other non-current assets | C18: 0 | D18: 0 | E18: 0 | F18: 658.35 | G18: 559.58 | H18: 676.46 | I18: Operating item
B19: Total Non-Current Assets | C19: 4563.3 | D19: 5274.63 | E19: 6584.79 | F19: 7741.49 | G19: 8394.5 | H19: 10091.15
B21: CURRENT ASSETS
B22: Inventories | C22: 669.55 | D22: 861.39 | E22: 761.99 | F22: 708.58 | G22: 962.68 | H22: 1249.53 | I22: Operating item
B23: Investments | C23: 3275.89 | D23: 2297.35 | E23: 3249.15 | F23: 4544.06 | G23: 5591.12 | H23: 3173.88 | I23: Non-Operating item
B24: Trade receivables | C24: 920.58 | D24: 1371.82 | E24: 1282.08 | F24: 1551.75 | G24: 1426.97 | H24: 2745.11 | I24: Operating item
B25: Cash and cash equivalents | C25: 119.83 | D25: 215.78 | E25: 179.09 | F25: 74.06 | G25: 130.61 | H25: 208.12 | I25: Operating item
B26: Bank balances | C26: 0 | D26: 0 | E26: 0 | F26: 121.33 | G26: 106.96 | H26: 95.78 | I26: Operating item
B27: Loans to employees | C27: 18.42 | D27: 23.86 | E27: 23.21 | F27: 21.73 | G27: 21.41 | H27: 23.22 | I27: Non-Operating item
B28: Security deposits | C28: 1.07 | D28: 0 | E28: 0 | F28: 3.2 | G28: 7.09 | H28: 1.86 | I28: Operating item
B29: Others Financial Assets | C29: 22.05 | D29: 59.97 | E29: 79.48 | F29: 145.02 | G29: 543.28 | H29: 654.19 | I29: Operating item
B30: Other current assets | C30: 530.89 | D30: 549.55 | E30: 511.91 | F30: 400.78 | G30: 212.11 | H30: 261.52 | I30: Operating item
B31: Total Current Assets | C31: 5558.28 | D31: 5379.72 | E31: 6086.91 | F31: 7570.51 | G31: 9002.23 | H31: 8413.21
B32: TOTAL ASSETS | C32: 10121.58 | D32: 10654.35 | E32: 12671.7 | F32: 15312 | G32: 17396.73 | H32: 18504.36
B34: Particulars | C34: 41699 | D34: 42064 | E34: 42430 | F34: 42795 | G34: 43160 | H34: 43525
B35: LIABILITIES
B36: NON-CURRENT LIABILITIES
B37: Equity share capital | C37: 39.94 | D37: 39.94 | E37: 39.94 | F37: 39.94 | G37: 39.94 | H37: 39.95 | I37: Non-Operating item
B38: Other equity | C38: 5582.7 | D38: 6500.06 | E38: 7912.74 | F38: 10275.57 | G38: 11931.52 | H38: 13080.46 | I38: Non-Operating item
B39: Non-controlling interests | C39: 0.85 | D39: 18.54 | E39: 53.62 | F39: 67.38 | G39: 93.21 | H39: 116.11 | I39: Non-Operating item
B40: LT Debt | C40: 0 | D40: 12 | E40: 145.98 | F40: 207.9 | G40: 149.63 | H40: 124.84 | I40: Non-Operating item
B41: Employee benefits | C41: 8.66 | D41: 10.19 | E41: 15.65 | F41: 16.17 | G41: 25.94 | H41: 28.41 | I41: Non-Operating item
B42: Other long - term liabilities | C42: 24.45 | D42: 31.33 | E42: 34.89 | F42: 0 | G42: 0 | H42: 0 | I42: Operating item
B43: Warranties | C43: 41.36 | D43: 56.06 | E43: 68.99 | F43: 59.45 | G43: 93.24 | H43: 92.53 | I43: Operating item
...
